Workbook

Sheet DJC20250829-261
B1: COMMERCIAL INVOICE
B4: 1. SHIPPER/EXPORTER | H4: 6. NO. & DATE OF INVOICE
B5: DONG JIN CORPORATION CO., LTD. | H5: DJC20250829-261 29, Aug, 2025.
B6: B144, Nakdong-daero 910, Sasang-gu, | H6: 7. PO NO.
B7: Busan City, The south of Korea.
B8: 47029 | H8: 8. TERMS OF DELIVERY AND PAYMENT
B9: Contact : Woo Jung Min | H9: CIF HCMC
B10: Tel)++82 10 2868 7653
B11: 2. RECEIVER/IMPORTER | H11: 9. PACKING
B12: Dong Jin Global Co., Ltd. | H12: EXPORTER'S STANDARD PACKING
B13: Lot 17, Road N11, Dat Do 1 Industrial Park, | H13: 10. BANK DETAIL
B14: Dat Do Commune, Ho Chi Minh City, Viet Nam
B15: Tel)++84 254 3688959
B16: Fax)++84 254 3866680
B19: 3. NOTIFY PARTY | H19: 11. REMARKS
H21: Tax code 3502336577
B23: 4. PORT OF LOADING | E23: 5. DESTINATION
B24: PUS PORT | E24: HCMC PORT
B26: 12. DESCRIPTIONS OF GOODS | E26: SPECIFICATION | H26: 13. QUANTITY/UNIT | J26: 14. UNIT-PRICE | L26: 15. AMOUNT
B27: MATERIAL TO MAKE WIRING HARNESS
B28: - Please refer to the attached document for details.
G30: TOTAL | H30: =DETAILS!E85 -> 1568400 | I30: EA | M30: =DETAILS!H85 -> 59923.6
H31: =DETAILS!E86 -> 130500 | I31: M
B63: 16. ISSUED BY : | H63: 17. ACCEPTED BY :
D64: DIRECTOR (WOO JUNG MIN) | J64: PRESIDENT (LEE SUNG JAE)
D65: DONGJIN CORPORATION CO., LTD. | J65: DONG JIN GLOBAL CO., LTD.

Sheet DETAILS
A1: Details of DJC20250829-261
A2: NO | B2: PART NAME | C2: PART NUMBER | D2: PROJECT | E2: Q'TY | F2: UNIT | G2: UNIT PRICE | H2: AMOUNT | I2: ORIGIN/MADE IN
A3: 1 | B3: CONNECTOR | C3: MG645605 | D3: MV/ME | E3: 3500 | F3: EA | G3: 0.134 | H3: =E3*G3 -> 469 | I3: KR
A4: 2 | B4: CONNECTOR | C4: MG651032 | D4: MV/ME | E4: 15000 | F4: EA | G4: 0.049 | H4: =E4*G4 -> 735 | I4: KR
A5: 3 | B5: CONNECTOR | C5: MG653026 | D5: MV/ME | E5: 6000 | F5: EA | G5: 0.126 | H5: =E5*G5 -> 756 | I5: KR
A6: 4 | B6: CONNECTOR | C6: CL6424-0049-2 | D6: MV/ME | E6: 45000 | F6: EA | G6: 0.101 | H6: =E6*G6 -> 4545 | I6: KR
A7: 5 | B7: CONNECTOR | C7: CL6432-0021-8 | D7: MV/ME | E7: 8000 | F7: EA | G7: 0.06 | H7: =E7*G7 -> 480 | I7: KR
A8: 6 | B8: CONNECTOR | C8: CL6439-0011-9 | D8: MV/ME | E8: 27000 | F8: EA | G8: 0.157 | H8: =E8*G8 -> 4239 | I8: KR
A9: 7 | B9: CONNECTOR | C9: MG655608 | D9: MV/ME | E9: 9000 | F9: EA | G9: 0.12 | H9: =E9*G9 -> 1080 | I9: KR
A10: 8 | B10: CONNECTOR | C10: MG645610 | D10: MV/ME | E10: 1500 | F10: EA | G10: 0.171 | H10: =E10*G10 -> 256.5 | I10: KR
A11: 9 | B11: CONNECTOR | C11: MG622937 | D11: MV/ME | E11: 3000 | F11: EA | G11: 0.047 | H11: =E11*G11 -> 141 | I11: KR
A12: 10 | B12: CONNECTOR | C12: MG652987 | D12: NQ5a PE HEV | E12: 14000 | F12: EA | G12: 0.057 | H12: =E12*G12 -> 798 | I12: KR
A13: 11 | B13: CONNECTOR | C13: KH2000062-20 | D13: NQ5e PE | E13: 12000 | F13: EA | G13: 0.055 | H13: =E13*G13 -> 660 | I13: KR
A14: 12 | B14: CONNECTOR | C14: MG642581-5 | D14: U100 | E14: 9000 | F14: EA | G14: 0.153 | H14: =E14*G14 -> 1377 | I14: KR
... A31: 29 | B31: BAND CABLE-A(GY) | C31: KPP011-99010 | D31: MV/ME | E31: 112000 | F31: EA | G31: 0.014 | H31: =E31*G31 -> 1568 | I31: KR
A32: 30 | B32: EMERHENCY RELEASE CABLE | C32: 603841 | D32: U100 | E32: 400 | F32: EA | G32: 2.925 | H32: =E32*G32 -> 1170 | I32: KR
A33: 31 | B33: CLIP | C33: MG634834-5 | D33: MV/ME | E33: 16000 | F33: EA | G33: 0.03 | H33: =E33*G33 -> 480 | I33: KR
A34: 32 | B34: CLIP | C34: GB080-02150 | D34: MV/ME | E34: 9600 | F34: EA | G34: 0.027 | H34: =E34*G34 -> 259.2 | I34: KR
A35: 33 | B35: CLIP | C35: MG634834-5 | D35: MV/ME | E35: 8000 | F35: EA | G35: 0.03 | H35: =E35*G35 -> 240 | I35: KR
A36: 34 | B36: SEAL | C36: MG685390 | D36: U100 | E36: 20000 | F36: EA | G36: 0.025 | H36: =E36*G36 -> 500 | I36: KR
A37: 35 | B37: SEAL | C37: CL6426-0060-8 | D37: U100 | E37: 20000 | F37: EA | G37: 0.018 | H37: =E37*G37 -> 360 | I37: KR
A38: 36 | B38: CABLE TIE | C38: 111-01747 | D38: U100 | E38: 50000 | F38: EA | G38: 0.034 | H38: =E38*G38 -> 1700 | I38: KR
A39: 37 | B39: TEMP SENSOR | C39: EP5F103N4-KP13-R | D39: U100 | E39: 500 | F39: EA | G39: 2.417 | H39: =E39*G39 -> 1208.5 | I39: KR
A40: 38 | B40: TEMP SENSOR | C40: EP5F103N4-KP13-L | D40: U100 | E40: 500 | F40: EA | G40: 2.417 | H40: =E40*G40 -> 1208.5 | I40: KR
A41: 39 | B41: HEAT SHRINK TUBE | C41: SSA024050 | D41: U100 | E41: 5000 | F41: EA | G41: 0.165 | H41: =E41*G41 -> 825 | I41: KR
A42: 40 | B42: CORRUGATE TUBE | C42: C19OR | D42: U100 | E42: 12000 | F42: M | G42: 0.279 | H42: =E42*G42 -> 3348 | I42: KR
A43: 41 | B43: CORRUGATE TUBE | C43: C12OR | D43: U100 | E43: 5000 | F43: M | G43: 0.136 | H43: =E43*G43 -> 680 | I43: KR
A44: 42 | B44: VYNIL TUBE | C44: VYNILTUBE003B | D44: NQ5e PE | E44: 3000 | F44: M | G44: 0.033 | H44: =E44*G44 -> 99 | I44: KR
... A84: 82 | B84: ELECTRIC WIRE | C84: AVSS03O | D84: NQ5e PE | E84: 1500 | F84: M | G84: 0.047 | H84: =E84*G84 -> 70.5 | I84: KR
A85: TOTAL | E85: =SUM(E3:E41,E45:E72) -> 1568400 | F85: EA | H85: =SUM(H3:H84) -> 59923.6
E86: =SUM(E42:E44,E73:E84) -> 130500 | F86: M

Sheet PACKING LIST
B1: PACKING LIST
B4: 1. SHIPPER/EXPORTER | H4: 6. NO. & DATE OF INVOICE
B5: DONG JIN CORPORATION CO., LTD. | H5: ='DJC20250829-261'!H5 -> DJC20250829-261 29, Aug, 2025.
B6: B144, Nakdong-daero 910, Sasang-gu, | H6: 7. PO NO.
B7: Busan City, The south of Korea.
B8: 47029 | H8: 8. TERMS OF DELIVERY AND PAYMENT
B9: Contact : Woo Jung Min | H9: CIF HCMC
B10: Tel)++82 10 2868 7653
B11: 2. RECEIVER/IMPORTER | H11: 9. PACKING
B12: Dong Jin Global Co., Ltd. | H12: EXPORTER'S STANDARD PACKING
B13: Lot 17, Road N11, Dat Do 1 Industrial Park, | H13: 10. BANK DETAIL
B14: Dat Do Commune, Ho Chi Minh City, Viet Nam
B15: Tel)++84 254 3688959
B16: Fax)++84 254 3866680
B19: 3. NOTIFY PARTY | H19: 11. REMARKS
B23: 4. PORT OF LOADING | E23: 5. DESTINATION
B24: PUS PORT | E24: HCMC PORT
B26: 12. DESCRIPTIONS OF GOODS | F26: Part Number | G26: P/NO | H26: 13. QUANTITY/UNIT | J26: 14. NET WEIGHT(KG) | K26: 15. GROSS WEIGHT(KG) | M26: 16.CBM
B28: MATERIAL TO MAKE WIRING HARNESS
B29: - Please refer to the attached document for details.
F33: TOTAL | H33: ='PACKING DETAIL'!D82 -> 1568400 | I33: EA | J33: 2149.31 | K33: 2364.241 | M33: 35.4
H34: ='PACKING DETAIL'!D83+'PACKING DETAIL'!D87 -> 130500 | I34: M
C43: EIGHTY-THREE(83) OF PACKAGES ONLY
B58: 17. ISSUED BY : | H58: 18. ACCEPTED BY :
D59: DIRECTOR (WOO JUNG MIN) | J59: ='[1]JBS20211018-001 INVOICE'!J57:M57 -> DIRECTOR (KIM YOUNG GON)
D60: DONGJIN CORPORATION CO., LTD. | J60: DONG JIN GLOBAL CO., LTD.

Sheet PACKING DETAIL
A1: PACKING LIST DETAIL OF DJC20250829-261
A2: NO | B2: PART NAME | C2: PART NUMBER | D2: Q'TY | E2: UNIT | F2: Net Weight (KG) | G2: Gross Weight (KG) | H2: Package No. | I2: CONTAINER | J2: CBM
A3: 1 | B3: CONNECTOR | C3: MG645605 | D3: 3500 | E3: EA | F3: 17.5 | G3: =F3*1.1 -> 19.25 | H3: 2 | I3: GAOU2012465 / CKL390350 | J3: 20.2
A4: 2 | B4: CONNECTOR | C4: MG651032 | D4: 15000 | E4: EA | F4: 15 | G4: =F4*1.1 -> 16.5 | H4: 2
A5: 3 | B5: CONNECTOR | C5: MG653026 | D5: 6000 | E5: EA | F5: 6 | G5: =F5*1.1 -> 6.6 | H5: 2
A6: 4 | B6: CONNECTOR | C6: CL6424-0049-2 | D6: 45000 | E6: EA | F6: 45 | G6: =F6*1.1 -> 49.5 | H6: 6,7
A7: 5 | B7: CONNECTOR | C7: CL6432-0021-8 | D7: 8000 | E7: EA | F7: 12 | G7: =F7*1.1 -> 13.2 | H7: 6,7
A8: 6 | B8: CONNECTOR | C8: CL6439-0011-9 | D8: 27000 | E8: EA | F8: 291.6 | G8: =F8*1.1 -> 320.76 | H8: 5
A9: 7 | B9: CONNECTOR | C9: MG655608 | D9: 9000 | E9: EA | F9: 13.5 | G9: =F9*1.1 -> 14.85 | H9: 2
A10: 8 | B10: CONNECTOR | C10: MG645610 | D10: 1500 | E10: EA | F10: 2.25 | G10: =F10*1.1 -> 2.475 | H10: 10
A11: 9 | B11: CONNECTOR | C11: MG622937 | D11: 3000 | E11: EA | F11: 4.5 | G11: =F11*1.1 -> 4.95 | H11: 10
A12: 10 | B12: CONNECTOR | C12: MG652987 | D12: 14000 | E12: EA | F12: 21 | G12: =F12*1.1 -> 23.1 | H12: 10
A13: 11 | B13: CONNECTOR | C13: KH2000062-20 | D13: 12000 | E13: EA | F13: 32 | G13: =F13*1.1 -> 35.2 | H13: 3
A14: 12 | B14: CONNECTOR | C14: MG642581-5 | D14: 9000 | E14: EA | F14: 72 | G14: =F14*1.1 -> 79.2 | H14: 2
A15: 13 | B15: CONNECTOR | C15: MG652582-5 | D15: 2500 | E15: EA | F15: 12.5 | G15: =F15*1.1 -> 13.75 | H15: 2
A16: 14 | B16: CONNECTOR | C16: MG681114 | D16: 20000 | E16: EA | F16: 10 | G16: =F16*1.1 -> 11 | H16: 2
A17: 15 | B17: CONNECTOR | C17: CL6405-0009-0 | D17: 3000 | E17: EA | F17: 1.5 | G17: =F17*1.1 -> 1.65 | H17: 6,7
A18: 16 | B18: TERMINAL | C18: ST741332-3 | D18: 82500 | E18: EA | F18: 8.25 | G18: =F18*1.1 -> 9.075 | H18: 2
A19: 17 | B19: TERMINAL | C19: ST730960-3 | D19: 20000 | E19: EA | F19: 23.2 | G19: =F19*1.1 -> 25.52 | H19: 2
A20: 18 | B20: TERMINAL | C20: CL6431-0013-3 | D20: 240000 | E20: EA | F20: 40.8 | G20: =F20*1.1 -> 44.88 | H20: 6,7
A21: 19 | B21: TERMINAL | C21: CL6431-0022-4-000 | D21: 55200 | E21: EA | F21: 16.01 | G21: =F21*1.1 -> 17.611 | H21: 6,7
A22: 20 | B22: TERMINAL | C22: CL6431-0007-0 | D22: 24000 | E22: EA | F22: 4.8 | G22: =F22*1.1 -> 5.28 | H22: 6,7
A23: 21 | B23: TERMINAL | C23: CL6432-0022-0-001 | D23: 35000 | E23: EA | F23: 3.5 | G23: =F23*1.1 -> 3.85 | H23: 6,7
A24: 22 | B24: TERMINAL | C24: CL6431-0011-8 | D24: 63000 | E24: EA | F24: 18.9 | G24: =F24*1.1 -> 20.79 | H24: 6,7
A25: 23 | B25: TERMINAL | C25: ST731053-3 | D25: 42000 | E25: EA | F25: 8.4 | G25: =F25*1.1 -> 9.24 | H25: 2
A26: 24 | B26: TERMINAL | C26: KH2000016-21 | D26: 90000 | E26: EA | F26: 27 | G26: =F26*1.1 -> 29.7 | H26: 3
A27: 25 | B27: TERMINAL | C27: ST710966-3 | D27: 4000 | E27: EA | F27: 8 | G27: =F27*1.1 -> 8.8 | H27: 2
A28: 26 | B28: TERMINAL | C28: ST760320-1 | D28: 50000 | E28: EA | F28: 10 | G28: =F28*1.1 -> 11 | H28: 2
A29: 27 | B29: TERMINAL | C29: CL6405-0015-2 | D29: 18000 | E29: EA | F29: 9 | G29: =F29*1.1 -> 9.9 | H29: 6,7
A30: 28 | B30: BAND CABLE-A5(B) | C30: GB080-01020 | D30: 19200 | E30: EA | F30: 41.4 | G30: =F30*1.1 -> 45.54 | H30: 4
A31: 29 | B31: BAND CABLE-A(GY) | C31: KPP011-99010 | D31: 112000 | E31: EA | F31: 22.4 | G31: =F31*1.1 -> 24.64 | H31: 4
A32: 30 | B32: EMERHENCY RELEASE CABLE | C32: 603841 | D32: 400 | E32: EA | F32: 29.6 | G32: =F32*1.1 -> 32.56 | H32: 3
A33: 31 | B33: CLIP | C33: MG634834-5 | D33: 16000 | E33: EA | F33: 6.4 | G33: =F33*1.1 -> 7.04 | H33: 2
A34: 32 | B34: CLIP | C34: GB080-02150 | D34: 9600 | E34: EA | F34: 14.4 | G34: =F34*1.1 -> 15.84 | H34: 4
A35: 33 | B35: CLIP | C35: MG634834-5 | D35: 8000 | E35: EA | F35: 12 | G35: =F35*1.1 -> 13.2 | H35: 10
A36: 34 | B36: SEAL | C36: MG685390 | D36: 20000 | E36: EA | F36: 4 | G36: =F36*1.1 -> 4.4 | H36: 2
A37: 35 | B37: SEAL | C37: CL6426-0060-8 | D37: 20000 | E37: EA | F37: 10 | G37: =F37*1.1 -> 11 | H37: 6,7
A38: 36 | B38: CABLE TIE | C38: 111-01747 | D38: 50000 | E38: EA | F38: 100 | G38: =F38*1.1 -> 110 | H38: 3
A39: 37 | B39: TEMP SENSOR | C39: EP5F103N4-KP13-R | D39: 500 | E39: EA | F39: 9 | G39: =F39*1.1 -> 9.9 | H39: 3
A40: 38 | B40: TEMP SENSOR | C40: EP5F103N4-KP13-L | D40: 500 | E40: EA | F40: 9 | G40: =F40*1.1 -> 9.9 | H40: 3
...
